Workbook

Sheet Instructions
A1: FinSight AI Validation Workbook — One Researcher
A3: Purpose | B3: Use this workbook to validate FinBERT sentiment classification, review OpenAI output, and record AI integration tests.
A4: Dataset target | B4: Use 60 CryptoCompare headlines: 20 positive, 20 negative, and 20 neutral after manual researcher labelling.
A5: Single-researcher design | B5: Only one human label column is used: researcher_label. It is treated as the ground-truth label for this individual FYP.
A6: Step 1 | B6: Run collect_cryptocompare_dataset_one_reviewer.py in the FinSight project root. It reads CRYPTOCOMPARE_API_KEY from the Laravel .env file.
A7: Step 2 | B7: Copy the selected CSV rows into the Headline Dataset sheet.
A8: Step 3 | B8: Manually review every headline and complete researcher_label before running FinBERT. Do not copy the provisional label automatically.
A9: Step 4 | B9: For mixed or unclear headlines, add a short explanation in notes.
A10: Step 5 | B10: Run all labelled headlines through the existing /analyze-sentiment endpoint and enter the prediction and probabilities.
A11: Step 6 | B11: The FinBERT Metrics sheet automatically calculates accuracy, precision, recall, per-class F1-score, macro F1-score, and confusion matrix.
A12: Report placement | B12: Summarise the dataset in Section 5.6.2 and provide the completed workbook or CSV as appendix/supplementary evidence.
A13: Limitation | B13: Because one researcher labelled the dataset, acknowledge possible subjectivity for ambiguous or mixed-sentiment headlines.

Sheet Headline Dataset
A1: FinBERT Cryptocurrency Headline Validation Dataset
A3: id | B3: headline | C3: source | D3: published_at | E3: crypto_asset | F3: article_url | G3: provisional_label | H3: researcher_label | I3: notes | J3: finbert_prediction | K3: positive_probability | L3: negative_probability | M3: neutral_probability | N3: correct
A4: 1 | B4: Japanese Yen: Intervention Risk Caps Downside Against US Dollar, Says MUFG | C4: bitcoinworld | D4: 2026-06-24 09:45:12 UTC | E4: GENERAL | F4: https://bitcoinworld.co.in/japanese-yen-intervention-risk-mufg-2/ | G4: positive | H4: positive | J4: negative | K4: 0.2226 | L4: 0.7454 | M4: 0.032 | N4: 0
A5: 2 | B5: Bitcoin Holds Near $63K as $589M Liquidations Hit, Tokenized RWA Tops $28B | C5: coinotag | D5: 2026-06-24 09:44:12 UTC | E5: BTC | F5: https://en.coinotag.com/bitcoin-holds-63k-589m-liquidations-tokenized-rwa-tops-28b | G5: negative | H5: positive | J5: positive | K5: 0.6601 | L5: 0.2225 | M5: 0.1174 | N5: 1
A6: 3 | B6: Is Saylor’s Strategy Sat on $1.5Bb Cashflow Problem? Grayscale Think So | C6: cryptonews | D6: 2026-06-24 09:46:09 UTC | E6: GENERAL | F6: https://cryptonews.com/news/strategy-bitcoin-sale-preferred-dividend-crisis/ | G6: neutral | H6: negative | J6: negative | K6: 0.0214 | L6: 0.7207 | M6: 0.2579 | N6: 1
A7: 4 | B7: Euro Extends Decline Against US Dollar as Firm Fed Rate Hike Bets Persist | C7: bitcoinworld | D7: 2026-06-24 09:40:11 UTC | E7: GENERAL | F7: https://bitcoinworld.co.in/euro-extends-decline-us-dollar-fed-rate-hike-bets/ | G7: positive | H7: negative | J7: negative | K7: 0.2477 | L7: 0.6732 | M7: 0.0791 | N7: 1
A8: 5 | B8: XRP fell below key support to $1.05-$1.10, retesting 2026 lows amid declining network activity | C8: cointurken | D8: 2026-06-24 09:24:05 UTC | E8: XRP | F8: https://en.coin-turk.com/xrp-fell-below-key-support-to-1-05-1-10-retesting-2026-lows-amid-declining-network-activity/?utm_source=rss&utm_medium=rss&utm_campaign=xrp-fell-below-key-support-to-1-05-1-10-retesting-2026-lows-amid-declining-network-activity | G8: negative | H8: negative | J8: negative | K8: 0.0148 | L8: 0.9751 | M8: 0.0101 | N8: 1
A9: 6 | B9: US House committee to discuss CLARITY Act on July 17, spotlight on XRP as regulatory clarity nears | C9: cointurken | D9: 2026-06-24 09:44:05 UTC | E9: XRP | F9: https://en.coin-turk.com/us-house-committee-to-discuss-clarity-act-on-july-17-spotlight-on-xrp-as-regulatory-clarity-nears/?utm_source=rss&utm_medium=rss&utm_campaign=us-house-committee-to-discuss-clarity-act-on-july-17-spotlight-on-xrp-as-regulatory-clarity-nears | G9: neutral | H9: neutral | J9: neutral | K9: 0.0661 | L9: 0.0226 | M9: 0.9113 | N9: 1
A10: 7 | B10: Bitcoin ticks up on positive U.S.-Iran talks, but gains capped by rate hike bets | C10: investing_comcryptonews | D10: 2026-06-24 09:17:28 UTC | E10: BTC | F10: https://www.investing.com/news/cryptocurrency-news/bitcoin-stalls-at-64k-amid-mixed-signals-on-usiran-talks-4751794 | G10: positive | H10: positive | J10: positive | K10: 0.8856 | L10: 0.0697 | M10: 0.0447 | N10: 1
A11: 8 | B11: HYPE price tests key $62 support as traders weigh rebound after 15% drop | C11: invezz | D11: 2026-06-24 09:23:16 UTC | E11: GENERAL | F11: https://invezz.com/news/2026/06/24/hype-price-tests-key-62-support-as-traders-weigh-rebound-after-15-drop/ | G11: negative | H11: negative | J11: positive | K11: 0.5728 | L11: 0.2845 | M11: 0.1427 | N11: 0
A12: 9 | B12: Can LINK price reclaim $8 as Chainlink targets real-time FX settlement? | C12: invezz | D12: 2026-06-24 09:40:56 UTC | E12: LINK | F12: https://invezz.com/news/2026/06/24/can-link-price-reclaim-8-as-chainlink-targets-real-time-fx-settlement/ | G12: neutral | H12: neutral | J12: neutral | K12: 0.1266 | L12: 0.0122 | M12: 0.8612 | N12: 1
A13: 10 | B13: XRP Futures Signal Bullish Sentiment as Price Slips to $1.1 | C13: bitcoinworld | D13: 2026-06-24 09:15:12 UTC | E13: XRP | F13: https://bitcoinworld.co.in/xrp-futures-bullish-sentiment-price-drop/ | G13: positive | H13: negative | J13: negative | K13: 0.0567 | L13: 0.9266 | M13: 0.0167 | N13: 1
A14: 11 | B14: Bitcoin’s Price Rejected at $63K as This Altcoin Explodes by 40%: Market Watch | C14: cryptopotato | D14: 2026-06-24 09:17:10 UTC | E14: BTC | F14: https://cryptopotato.com/bitcoins-price-rejected-at-63k-as-this-altcoin-explodes-by-40-market-watch/ | G14: negative | H14: neutral | I14: Neutral because the headline combines negative Bitcoin performance with strong positive altcoin performance. | J14: neutral | K14: 0.2 | L14: 0.1247 | M14: 0.6753 | N14: 1
A15: 12 | B15: BTC price four-year trend calls for $76K as analysis says Bitcoin 'not broken' | C15: cointelegraph | D15: 2026-06-24 09:40:13 UTC | E15: BTC | F15: https://cointelegraph.com/markets/bitcoin-four-year-trend-calls-for-76k-as-analysis-says-btc-price-not-broken?utm_source=rss&utm_medium=rss&utm_campaign=rss | G15: neutral | H15: positive | I15: Positive because the analysis suggests an upside target and continued strength in Bitcoin’s long-term trend. | J15: positive | K15: 0.6704 | L15: 0.1781 | M15: 0.1515 | N15: 1
A16: 13 | B16: New Listings Surge! HTX Weekly Recap (June 15–21): Newly Listed RE and O Prices Double Upon Debut While DeFi Emerges as the Dominant Market Narrative | C16: huobi | D16: 2026-06-24 09:11:35 UTC | E16: GENERAL | F16: https://square.htx.com/new-listings-surge-htx-weekly-recap-june-15-21-newly-listed-re-and-o-prices-double-upon-debut-while-defi-emerges-as-the-dominant-market-narrative/ | G16: positive | H16: positive | J16: positive | K16: 0.9432 | L16: 0.0261 | M16: 0.0307 | N16: 1
A17: 14 | B17: Bitcoin Faces Potential Drop to $46,000 If Key Support at $60,587 Fails, Analyst Warns | C17: bitcoinworld | D17: 2026-06-24 09:00:12 UTC | E17: BTC | F17: https://bitcoinworld.co.in/bitcoin-potential-drop-46000-support-fails-ali-martinez/ | G17: negative | H17: negative | J17: negative | K17: 0.0122 | L17: 0.9702 | M17: 0.0176 | N17: 1
A18: 15 | B18: XRP Holds $1.10 as Whales Net 1.53B Tokens While Derivatives Bets Split on CLARITY Act | C18: coinotag | D18: 2026-06-24 09:38:55 UTC | E18: XRP | F18: https://en.coinotag.com/xrp-holds-1-10-whales-net-1-53b-derivatives-split-clarity-act | G18: neutral | H18: neutral | J18: neutral | K18: 0.0762 | L18: 0.0326 | M18: 0.8912 | N18: 1
A19: 16 | B19: Virell Trade Launches Stabliq Wallet for Stablecoin Management on Ethereum and TRON | C19: investing_comcryptonews | D19: 2026-06-24 09:06:21 UTC | E19: ETH | F19: https://www.investing.com/news/cryptocurrency-news/virell-trade-launches-stabliq-wallet-for-stablecoin-management-on-ethereum-and-tron-4757582 | G19: positive | H19: neutral | J19: neutral | K19: 0.2109 | L19: 0.0078 | M19: 0.7814 | N19: 1
A20: 17 | B20: THORChain resumes trading 39 days after $10.7 million vault exploit | C20: coinpaprika | D20: 2026-06-24 09:00:00 UTC | E20: GENERAL | F20: https://coinpaprika.com/news/thorchain-resumes-trading-39-days-107-million | G20: negative | H20: neutral | I20: Trading resumption is positive, but the headline also highlights a major exploit and lengthy disruption. The signals are mixed. | J20: neutral | K20: 0.1102 | L20: 0.0848 | M20: 0.8049 | N20: 1
A21: 18 | B21: Here’s How the Catholic Church Could Kill CLARITY Act Over Human Trafficking | C21: cryptonews | D21: 2026-06-24 09:36:09 UTC | E21: GENERAL | F21: https://cryptonews.com/news/clarity-act-defi-exemption-catholic-leaders-aml/ | G21: neutral | H21: neutral | J21: neutral | K21: 0.0349 | L21: 0.0706 | M21: 0.8945 | N21: 1
A22: 19 | B22: Silver Price Stages Recovery From Six-Month Lows: What’s Driving the Move | C22: bitcoinworld | D22: 2026-06-24 08:30:11 UTC | E22: GENERAL | F22: https://bitcoinworld.co.in/silver-price-rebound-xagusd-six-month-lows/ | G22: positive | H22: positive | J22: neutral | K22: 0.1383 | L22: 0.2414 | M22: 0.6204 | N22: 0
A23: 20 | B23: Chainlink selected as key technology provider for $10 trillion cross border payment project with 47 banks | C23: cointurken | D23: 2026-06-24 08:53:05 UTC | E23: LINK | F23: https://en.coin-turk.com/chainlink-selected-as-key-technology-provider-for-10-trillion-cross-border-payment-project-with-47-banks/?utm_source=rss&utm_medium=rss&utm_campaign=chainlink-selected-as-key-technology-provider-for-10-trillion-cross-border-payment-project-with-47-banks | G23: negative | H23: positive | I23: It indicates major institutional adoption and a significant technology partnership for Chainlink. | J23: positive | K23: 0.856 | L23: 0.0072 | M23: 0.1367 | N23: 1
A24: 21 | B24: European Bond Yields Slide as Falling Oil Prices Calm Inflation Fears | C24: bitcoinworld | D24: 2026-06-24 09:35:11 UTC | E24: GENERAL | F24: https://bitcoinworld.co.in/european-bond-yields-slide-oil-prices-inflation/ | G24: neutral | H24: negative | J24: negative | K24: 0.0194 | L24: 0.9313 | M24: 0.0493 | N24: 1
A25: 22 | B25: US Dollar Rally Extends to Fresh 13-Month High: What’s Driving the Surge? | C25: bitcoinworld | D25: 2026-06-24 08:15:11 UTC | E25: GENERAL | F25: https://bitcoinworld.co.in/us-dollar-rally-13-month-high/ | G25: positive | H25: neutral | J25: neutral | K25: 0.2004 | L25: 0.1474 | M25: 0.6522 | N25: 1
A26: 23 | B26: Bitcoin bulls face $64,000 test as ETF outflows weaken sentiment | C26: invezz | D26: 2026-06-24 08:38:03 UTC | E26: BTC | F26: https://invezz.com/news/2026/06/24/bitcoin-bulls-face-64000-test-as-etf-outflows-weaken-sentiment/ | G26: negative | H26: negative | J26: negative | K26: 0.0137 | L26: 0.9682 | M26: 0.0181 | N26: 1
A27: 24 | B27: Tempting levels reached in Strategy’s Bitcoin reserves! What is the concern that has investors on alert? | C27: cointurken | D27: 2026-06-24 09:32:05 UTC | E27: BTC | F27: https://en.coin-turk.com/tempting-levels-reached-in-strategys-bitcoin-reserves-what-is-the-concern-that-has-investors-on-alert/?utm_source=rss&utm_medium=rss&utm_campaign=tempting-levels-reached-in-strategys-bitcoin-reserves-what-is-the-concern-that-has-investors-on-alert | G27: neutral | H27: neutral | J27: neutral | K27: 0.0692 | L27: 0.1946 | M27: 0.7363 | N27: 1
A28: 25 | B28: USD/CAD Rally Extends Beyond 1.4200 as US Dollar Continues to Outperform | C28: bitcoinworld | D28: 2026-06-24 07:55:11 UTC | E28: GENERAL | F28: https://bitcoinworld.co.in/usd-cad-rally-extends-beyond-1-4200/ | G28: positive | H28: positive | J28: positive | K28: 0.9355 | L28: 0.0389 | M28: 0.0256 | N28: 1
A29: 26 | B29: Singapore Dollar Under Pressure as US Dollar Strengthens: Commerzbank | C29: bitcoinworld | D29: 2026-06-24 08:35:11 UTC | E29: GENERAL | F29: https://bitcoinworld.co.in/singapore-dollar-pressure-us-dollar-commerzbank/ | G29: negative | H29: negative | I29: The Singapore dollar is weakening and facing pressure against the US dollar. | J29: positive | K29: 0.6573 | L29: 0.2906 | M29: 0.0521 | N29: 0
A30: 27 | B30: Hut 8 Investors Reach $2.35 Million Settlement Over US Bitcoin Merger Claims | C30: bitcoin.com | D30: 2026-06-24 09:30:50 UTC | E30: BTC | F30: https://news.bitcoin.com/hut-8-investors-reach-2-35-million-settlement-over-us-bitcoin-merger-claims/ | G30: neutral | H30: negative | I30: The headline concerns legal claims and a financial settlement related to Hut 8’s merger, indicating an adverse corporate event. | J30: positive | K30: 0.5624 | L30: 0.3706 | M30: 0.067 | N30: 0
A31: 28 | B31: CBOE Launches Prediction Markets With S&P 500 Binary Contracts | C31: cryptopotato | D31: 2026-06-24 07:26:40 UTC | E31: GENERAL | F31: https://cryptopotato.com/cboe-launches-prediction-markets-with-sp-500-binary-contracts/ | G31: positive | H31: positive | I31: The launch represents product expansion and a new market offering by CBOE. | J31: neutral | K31: 0.0678 | L31: 0.0133 | M31: 0.9189 | N31: 0
A32: 29 | B32: Solana fell over 5% in 24 hours as whales opened major short positions near $69 | C32: cointurken | D32: 2026-06-24 08:32:12 UTC | E32: SOL | F32: https://en.coin-turk.com/solana-fell-over-5-in-24-hours-as-whales-opened-major-short-positions-near-69/?utm_source=rss&utm_medium=rss&utm_campaign=solana-fell-over-5-in-24-hours-as-whales-opened-major-short-positions-near-69 | G32: negative | H32: negative | J32: negative | K32: 0.0105 | L32: 0.975 | M32: 0.0145 | N32: 1
A33: 30 | B33: Bithumb Refuses to Support Humanity (H) Token Swap, Flags Investor Protection Gaps | C33: bitcoinworld | D33: 2026-06-24 09:30:10 UTC | E33: GENERAL | F33: https://bitcoinworld.co.in/bithumb-humanity-h-token-swap/ | G33: neutral | H33: negative | J33: negative | K33: 0.0303 | L33: 0.5044 | M33: 0.4653 | N33: 1
A34: 31 | B34: Dollar Surges Past 1,545 Won in Intraday Trading, Marking 19-Day High | C34: bitcoinworld | D34: 2026-06-24 07:25:11 UTC | E34: GENERAL | F34: https://bitcoinworld.co.in/dollar-surges-past-1545-won-intraday/ | G34: positive | H34: positive | J34: positive | K34: 0.9259 | L34: 0.0383 | M34: 0.0358 | N34: 1
A35: 32 | B35: US House Sends Fed CBDC Ban to Trump’s Desk as Housing Bill Clears Congress | C35: bitcoin.com | D35: 2026-06-24 08:30:15 UTC | E35: GENERAL | F35: https://news.bitcoin.com/us-house-fed-cbdc-ban-trump-2030/ | G35: negative | H35: neutral | I35: Neutral because it reports a factual regulatory decision without describing a direct favourable or adverse market impact. | J35: neutral | K35: 0.1071 | L35: 0.0687 | M35: 0.8242 | N35: 1
A36: 33 | B36: OKX to List Nesa (NES) for Spot Trading Today | C36: bitcoinworld | D36: 2026-06-24 09:25:11 UTC | E36: GENERAL | F36: https://bitcoinworld.co.in/okx-lists-nesa-nes-spot-trading/ | G36: neutral | H36: neutral | J36: neutral | K36: 0.0257 | L36: 0.0207 | M36: 0.9536 | N36: 1
A37: 34 | B37: Trump lands in Senate's crosshairs over $500 million UAE investment in his crypto venture | C37: coindesk | D37: 2026-06-24 07:18:21 UTC | E37: GENERAL | F37: https://www.coindesk.com/policy/2026/06/24/trump-lands-in-senate-s-crosshairs-over-usd500-million-uae-investment-in-his-crypto-venture | G37: positive | H37: neutral | J37: neutral | K37: 0.1282 | L37: 0.0176 | M37: 0.8543 | N37: 1
A38: 35 | B38: Tech-Led Decline Weighs on US Equities, Deutsche Bank Reports | C38: bitcoinworld | D38: 2026-06-24 08:25:11 UTC | E38: GENERAL | F38: https://bitcoinworld.co.in/tech-led-decline-us-equities-deutsche-bank/ | G38: negative | H38: negative | J38: negative | K38: 0.0417 | L38: 0.9203 | M38: 0.038 | N38: 1
A39: 36 | B39: Crypto News, June 24: Crypto Chaos as BTC USD Tumbles with Chip Stocks, ETH Foundation Axes Staff, Rate Hike Looms | C39: cryptonews | D39: 2026-06-24 09:23:41 UTC | E39: BTC,ETH | F39: https://cryptonews.com/news/crypto-news-june-24-crypto-chaos-as-btc-usd-tumbles-with-chip-stocks-eth-foundation-axes-staff-rate-hike-looms/ | G39: neutral | H39: negative | I39: The headline combines falling Bitcoin prices, staff cuts, and the risk of higher interest rates, all of which indicate adverse market conditions. | J39: negative | K39: 0.0267 | L39: 0.9333 | M39: 0.0401 | N39: 1
A40: 37 | B40: OpenPayd secures MiCA license as stablecoin adoption grows in Europe | C40: cointelegraph | D40: 2026-06-24 07:17:46 UTC | E40: GENERAL | F40: https://cointelegraph.com/news/openpayd-mica-license-stablecoin-adoption-europe?utm_source=rss&utm_medium=rss&utm_campaign=rss | G40: positive | H40: positive | J40: positive | K40: 0.8271 | L40: 0.0057 | M40: 0.1672 | N40: 1
A41: 38 | B41: MSTR Stock Crash: Investors Fear Dilution as Bitcoin Holdings Grow | C41: coinpedia | D41: 2026-06-24 08:14:57 UTC | E41: BTC | F41: https://coinpedia.org/news/wall-street-losing-interest-in-michael-saylor-google-trends-shows-drop-in-mstr-stock/ | G41: negative | H41: negative | J41: negative | K41: 0.0169 | L41: 0.9257 | M41: 0.0574 | N41: 1
...

Sheet FinBERT Metrics
A1: FinBERT Evaluation Metrics
A3: Researcher Label Distribution | B3: Count
A4: Positive | B4: =COUNTIF('Headline Dataset'!$H$4:$H$203,"positive") -> 16
A5: Negative | B5: =COUNTIF('Headline Dataset'!$H$4:$H$203,"negative") -> 26
A6: Neutral | B6: =COUNTIF('Headline Dataset'!$H$4:$H$203,"neutral") -> 18
A7: Total | B7: =COUNTA('Headline Dataset'!$H$4:$H$203) -> 60
A10: Sentiment Class | B10: Precision | C10: Recall | D10: F1-Score | E10: Number of Headlines
A11: Positive | B11: =IFERROR(COUNTIFS('Headline Dataset'!$H$4:$H$203,"positive",'Headline Dataset'!$J$4:$J$203,"positive")/COUNTIF('Headline Dataset'!$J$4:$J$203,"positive"),0) -> 0.75 | C11: =IFERROR(COUNTIFS('Headline Dataset'!$H$4:$H$203,"positive",'Headline Dataset'!$J$4:$J$203,"positive")/COUNTIF('Headline Dataset'!$H$4:$H$203,"positive"),0) -> 0.75 | D11: =IFERROR(2*B11*C11/(B11+C11),0) -> 0.75 | E11: =COUNTIF('Headline Dataset'!$H$4:$H$203,"positive") -> 16
A12: Negative | B12: =IFERROR(COUNTIFS('Headline Dataset'!$H$4:$H$203,"negative",'Headline Dataset'!$J$4:$J$203,"negative")/COUNTIF('Headline Dataset'!$J$4:$J$203,"negative"),0) -> 0.92 | C12: =IFERROR(COUNTIFS('Headline Dataset'!$H$4:$H$203,"negative",'Headline Dataset'!$J$4:$J$203,"negative")/COUNTIF('Headline Dataset'!$H$4:$H$203,"negative"),0) -> 0.88461538 | D12: =IFERROR(2*B12*C12/(B12+C12),0) -> 0.90196078 | E12: =COUNTIF('Headline Dataset'!$H$4:$H$203,"negative") -> 26
A13: Neutral | B13: =IFERROR(COUNTIFS('Headline Dataset'!$H$4:$H$203,"neutral",'Headline Dataset'!$J$4:$J$203,"neutral")/COUNTIF('Headline Dataset'!$J$4:$J$203,"neutral"),0) -> 0.89473684 | C13: =IFERROR(COUNTIFS('Headline Dataset'!$H$4:$H$203,"neutral",'Headline Dataset'!$J$4:$J$203,"neutral")/COUNTIF('Headline Dataset'!$H$4:$H$203,"neutral"),0) -> 0.94444444 | D13: =IFERROR(2*B13*C13/(B13+C13),0) -> 0.91891892 | E13: =COUNTIF('Headline Dataset'!$H$4:$H$203,"neutral") -> 18
A14: Macro Average | B14: =AVERAGE(B11:B13) -> 0.85491228 | C14: =AVERAGE(C11:C13) -> 0.85968661 | D14: =AVERAGE(D11:D13) -> 0.8569599 | E14: =SUM(E11:E13) -> 60
A16: Overall Accuracy | B16: =IFERROR(SUM('Headline Dataset'!$N$4:$N$203)/COUNT('Headline Dataset'!$N$4:$N$203),0) -> 0.86666667
A19: Actual Researcher Label | B19: Predicted Positive | C19: Predicted Negative | D19: Predicted Neutral
A20: Positive | B20: =COUNTIFS('Headline Dataset'!$H$4:$H$203,"positive",'Headline Dataset'!$J$4:$J$203,"positive") -> 12 | C20: =COUNTIFS('Headline Dataset'!$H$4:$H$203,"positive",'Headline Dataset'!$J$4:$J$203,"negative") -> 2 | D20: =COUNTIFS('Headline Dataset'!$H$4:$H$203,"positive",'Headline Dataset'!$J$4:$J$203,"neutral") -> 2
A21: Negative | B21: =COUNTIFS('Headline Dataset'!$H$4:$H$203,"negative",'Headline Dataset'!$J$4:$J$203,"positive") -> 3 | C21: =COUNTIFS('Headline Dataset'!$H$4:$H$203,"negative",'Headline Dataset'!$J$4:$J$203,"negative") -> 23 | D21: =COUNTIFS('Headline Dataset'!$H$4:$H$203,"negative",'Headline Dataset'!$J$4:$J$203,"neutral") -> 0
A22: Neutral | B22: =COUNTIFS('Headline Dataset'!$H$4:$H$203,"neutral",'Headline Dataset'!$J$4:$J$203,"positive") -> 1 | C22: =COUNTIFS('Headline Dataset'!$H$4:$H$203,"neutral",'Headline Dataset'!$J$4:$J$203,"negative") -> 0 | D22: =COUNTIFS('Headline Dataset'!$H$4:$H$203,"neutral",'Headline Dataset'!$J$4:$J$203,"neutral") -> 17

Sheet OpenAI Review
A1: OpenAI Market Abstract and Deep Dive Human Review
A3: scenario_id | B3: scenario_type | C3: asset | D3: input_headlines_summary | E3: finbert_dominant_sentiment | F3: risk_score | G3: risk_level | H3: generated_output | I3: relevance | J3: sentiment_consistency | K3: factual_grounding | L3: clarity | M3: conciseness | N3: key_driver_identification | O3: safety | P3: average_score | Q3: researcher_comments
A4: S01 | B4: Market Abstract | C4: Positive | D4: MARKET | E4: 7, 13, 20, 48, 57 | F4: Bitcoin ticks up on positive U.S.-Iran talks, but gains capped by rate hike bets | New Listings Surge! HTX Weekly Recap (June 15–21): Newly Listed RE and O Prices Double Upon Debut While DeFi Emerges as the Dominant Market Narrative | Chainlink selected as key technology provider for $10 trillion cross border payment project with 47 banks | Tokenized Stocks Triple Holder Count Since January as Transfer Volume Hits Record $2.2B | BVI emerges as a global hub for tokenised finance, accounting for $1.2bn in stablecoins | G4: 0.8986 | H4: 0.0354 | I4: 0.0659 | J4: positive | K4: 4 | L4: Low | M4: Market sentiment remains strongly positive, with the Positive reading dominating at about 0.90 and signaling constructive conditions for crypto and related assets. Bitcoin edged higher on positive U.S.-Iran talks but gains are tempered by rate-hike expectations, while tokenized finance advances appear broadening, including Chainlink’s role in a $10 trillion cross-border project and a surge in tokenized stocks. The week also features a surge in new listings and BVI’s emergence as a hub for tokenised finance, underscoring broader adoption signals. | N4: 5 | O4: 5 | P4: 5 | Q4: 5
A5: S02 | B5: Deep Dive | C5: Positive | D5: BTC | E5: 2, 7, 12, 55 | F5: Bitcoin Holds Near $63K as $589M Liquidations Hit, Tokenized RWA Tops $28B | Bitcoin ticks up on positive U.S.-Iran talks, but gains capped by rate hike bets | BTC price four-year trend calls for $76K as analysis says Bitcoin 'not broken' | Bitcoin Approaches $60K Support as Institutional ETF Inflows Stall: Analysis | G5: 0.7795 | H5: 0.1362 | I5: 0.0844 | J5: positive | K5: 14 | L5: Low | M5: Bitcoin’s near-term moves are driven by macro policy expectations and evolving institutional demand. Growing institutional activity (ETF inflows) and the expansion of tokenized real-world assets provide price support around key levels, including near $60k. Yet rate-hike bets and occasional liquidations keep upside gains capped in a cautious, mixed-sentiment environment. | N5: 5 | O5: 4 | P5: 3 | Q5: 5
A6: S03 | B6: Market Abstract | C6: Positive | D6: MARKET | E6: 13, 20, 48, 52, 57 | F6: New Listings Surge! HTX Weekly Recap (June 15–21): Newly Listed RE and O Prices Double Upon Debut While DeFi Emerges as the Dominant Market Narrative | Chainlink selected as key technology provider for $10 trillion cross border payment project with 47 banks | Tokenized Stocks Triple Holder Count Since January as Transfer Volume Hits Record $2.2B | CLARITY Act Hits 80-Group Revolt as SBI Wins JPYSC Approval, Polymarket Tops $3B | BVI emerges as a global hub for tokenised finance, accounting for $1.2bn in stablecoins | G6: 0.8977 | H6: 0.0268 | I6: 0.0755 | J6: positive | K6: 3 | L6: Low | M6: Market sentiment is strongly positive (dominant around 0.898), signaling ongoing optimism. Recent headlines point to a DeFi-forward expansion and a wave of tokenization, including surging new listings, tokenized stocks growth, and major infrastructure wins like Chainlink’s cross-border payment project. No financial advice. | N6: 5 | O6: 5 | P6: 5 | Q6: 5
A7: S04 | B7: Market Abstract | C7: Negative | D7: MARKET | E7: 5, 14, 23, 50, 58 | F7: XRP fell below key support to $1.05-$1.10, retesting 2026 lows amid declining network activity | Bitcoin Faces Potential Drop to $46,000 If Key Support at $60,587 Fails, Analyst Warns | Bitcoin bulls face $64,000 test as ETF outflows weaken sentiment | Crypto Market Remains Under Pressure as Wave 5 Decline Threatens | Ethereum Foundation Cuts 54 Jobs, Ethlabs Launches as ETH Slips Near $1,670 | G7: 0.016 | H7: 0.9643 | I7: 0.0198 | J7: negative | K7: 96 | L7: High | M7: Market sentiment remains dominated by negativity, indicating ongoing downside pressure across assets. In crypto, XRP fell below key support around $1.05–$1.10 and Bitcoin faces a potential drop toward $46,000 if the $60,587 level fails, with ETF outflows and Wave 5 decline threats weighing on sentiment. Ethereum trades near $1,670 as the Ethereum Foundation cuts 54 jobs and Ethlabs launches. | N7: 5 | O7: 5 | P7: 5 | Q7: 5
A8: S05 | B8: Deep Dive | C8: Negative | D8: BTC | E8: 14, 23, 36, 44 | F8: Bitcoin Faces Potential Drop to $46,000 If Key Support at $60,587 Fails, Analyst Warns | Bitcoin bulls face $64,000 test as ETF outflows weaken sentiment | Crypto News, June 24: Crypto Chaos as BTC USD Tumbles with Chip Stocks, ETH Foundation Axes Staff, Rate Hike Looms | Bitcoin Warning: Here’s Why BTC’s Price Could Crash Below $38K (Analyst) | G8: 0.0196 | H8: 0.9001 | I8: 0.0804 | J8: negative | K8: 90 | L8: High | M8: BTC is a high-risk asset (risk score 90/100) with overwhelmingly negative sentiment, making price moves highly sensitive to macro factors. The main market driver is shifting liquidity and risk appetite—driven by rate-hike expectations and ETF outflows—amplified by key technical levels (support around $60,587 and resistance near $64,000). Recent headlines warn of sharp downside if support fails (potential drop toward $46,000), reflecting fragile sentiment and leverage dynamics. | N8: 5 | O8: 5 | P8: 4 | Q8: 5
A9: S06 | B9: Deep Dive | C9: Negative | D9: ETH | E9: 36, 46, 56, 58 | F9: Crypto News, June 24: Crypto Chaos as BTC USD Tumbles with Chip Stocks, ETH Foundation Axes Staff, Rate Hike Looms | Ethereum USD Price Remains Stuck Below $1,800 as Bullish Momentum Fades | Binance ETH Futures Open Interest Sinks to Three-Month Low as Prices Slump | Ethereum Foundation Cuts 54 Jobs, Ethlabs Launches as ETH Slips Near $1,670 | G9: 0.0265 | H9: 0.9225 | I9: 0.0511 | J9: negative | K9: 92 | L9: High | M9: ETH is high-risk (92/100) due to macro tightening, overwhelmingly negative sentiment, and liquidity stress. Latest headlines show price stuck below $1,800, Ethereum Foundation staff cuts, and Binance ETH futures open interest at a three-month low. The key market driver is macro policy and sentiment shifts that dampen demand and liquidity, increasing the likelihood of sharp price moves. | N9: 5 | O9: 5 | P9: 4 | Q9: 5
A10: S07 | B10: Market Abstract | C10: Neutral | D10: MARKET | E10: 6, 15, 32, 33, 45 | F10: US House committee to discuss CLARITY Act on July 17, spotlight on XRP as regulatory clarity nears | XRP Holds $1.10 as Whales Net 1.53B Tokens While Derivatives Bets Split on CLARITY Act | US House Sends Fed CBDC Ban to Trump’s Desk as Housing Bill Clears Congress | OKX to List Nesa (NES) for Spot Trading Today | Securitize Tokenizes Roubini-Linked ETF Under Dubai VARA Framework | G10: 0.0631 | H10: 0.0314 | I10: 0.9055 | J10: neutral | K10: 3 | L10: Low | M10: Market sentiment remains broadly neutral, with Neutral at 90.6%, Positive 6.3%, and Negative 3.1%. The dominant sentiment is neutral as investors digest regulatory headlines, including the CLARITY Act’s XRP spotlight and ongoing CBDC policy discussions. Notable crypto headlines point to activity like OKX listing NES and Securitize tokenizing a Dubai VARA-regulated ETF. | N10: 5 | O10: 5 | P10: 5 | Q10: 5
A11: S08 | B11: Deep Dive | C11: Neutral | D11: BTC | E11: 11, 24, 39, 54 | F11: Bitcoin’s Price Rejected at $63K as This Altcoin Explodes by 40%: Market Watch | Tempting levels reached in Strategy’s Bitcoin reserves! What is the concern that has investors on alert? | CryptoQuant Says Strategy Should Pause Bitcoin Buys And Rebuild Cash Reserves | CryptoQuant warned Strategy to pause Bitcoin purchases as cash reserves cover only 14 months of STRC dividends | G11: 0.1696 | H11: 0.1635 | I11: 0.6669 | J11: neutral | K11: 16 | L11: Low | M11: BTC’s near-term dynamics are driven by a key price hurdle around $63,000, where price rejection has focused attention on demand. Headlines also indicate a strategy fund may pause BTC purchases to rebuild cash reserves, potentially reducing buying pressure and liquidity. Overall, sentiment is mostly neutral with a low risk score, but the interaction between resistance and large-holder demand remains the primary driver. | N11: 5 | O11: 5 | P11: 4 | Q11: 5
A12: S09 | B12: Market Abstract | C12: Neutral | D12: MARKET | E12: 16, 33, 45, 51 | F12: Virell Trade Launches Stabliq Wallet for Stablecoin Management on Ethereum and TRON | OKX to List Nesa (NES) for Spot Trading Today | Securitize Tokenizes Roubini-Linked ETF Under Dubai VARA Framework | Bitmine reports 5.67 million ETH holdings, total assets of $10.7B | G12: 0.0788 | H12: 0.0142 | I12: 0.907 | J12: neutral | K12: 1 | L12: Low | M12: Market remains broadly rangebound with a predominantly neutral tone, as Neutral sentiment dominates at 0.907 (Positive 0.0788, Negative 0.0142). Recent headlines highlight ongoing infrastructure and liquidity activity, including Stabliq Wallet for stablecoins on Ethereum/TRON, OKX’s NES listing, Dubai VARA-tokenization via Securitize, and Bitmine’s large ETH holdings. No financial advice is provided. | N12: 5 | O12: 5 | P12: 5 | Q12: 5
A13: S10 | B13: Market Abstract | C13: Mixed | D13: MARKET | E13: 2, 5, 33, 48, 58 | F13: Bitcoin Holds Near $63K as $589M Liquidations Hit, Tokenized RWA Tops $28B | XRP fell below key support to $1.05-$1.10, retesting 2026 lows amid declining network activity | OKX to List Nesa (NES) for Spot Trading Today | Tokenized Stocks Triple Holder Count Since January as Transfer Volume Hits Record $2.2B | Ethereum Foundation Cuts 54 Jobs, Ethlabs Launches as ETH Slips Near $1,670 | G13: 0.3231 | H13: 0.4473 | I13: 0.2296 | J13: negative | K13: 45 | L13: Medium | M13: Market sentiment remains negative, the dominant reading at Negative 0.4473 signaling a cautious stance. Bitcoin holds near $63K as $589M in liquidations hit, ETH sits around $1,670 and XRP tests key support around $1.05–$1.10 amid subdued network activity; tokenized markets show traction with tokenized RWA topping $28B and NES set for spot listing. No financial advice. | N13: 5 | O13: 5 | P13: 5 | Q13: 4
A14: S11 | B14: Deep Dive | C14: Mixed | D14: BTC | E14: 7, 11, 14, 55 | F14: Bitcoin ticks up on positive U.S.-Iran talks, but gains capped by rate hike bets | Bitcoin’s Price Rejected at $63K as This Altcoin Explodes by 40%: Market Watch | Bitcoin Faces Potential Drop to $46,000 If Key Support at $60,587 Fails, Analyst Warns | Bitcoin Approaches $60K Support as Institutional ETF Inflows Stall: Analysis | G14: 0.4999 | H14: 0.3098 | I14: 0.1904 | J14: positive | K14: 31 | L14: Low | M14: Bitcoin’s near-term price action is largely driven by macro-financial dynamics, especially expectations around U.S. rate hikes and related policy signals that can cap gains. Institutional demand via ETF inflows (or their absence) and key technical levels around $60k–$63k act as major accelerants or barriers, echoed by headlines about price rejections and potential drops if support fails. | N14: 5 | O14: 4 | P14: 5 | Q14: 5
A15: S12 | B15: Deep Dive | C15: Mixed | D15: XRP | E15: 5, 6, 10, 15, 47 | F15: XRP fell below key support to $1.05-$1.10, retesting 2026 lows amid declining network activity | US House committee to discuss CLARITY Act on July 17, spotlight on XRP as regulatory clarity nears | XRP Futures Signal Bullish Sentiment as Price Slips to $1.1 | XRP Holds $1.10 as Whales Net 1.53B Tokens While Derivatives Bets Split on CLARITY Act | XRP weekly losses have exceeded 10 percent! What’s happening at this critical threshold? | G15: 0.0471 | H15: 0.5425 | I15: 0.4104 | J15: negative | K15: 54 | L15: Medium | M15: Regulatory clarity expectations around the CLARITY Act are the primary market driver for XRP now, shaping sentiment and trader positioning ahead of a House committee discussion. This is paired with waning network activity and a test of support near $1.05–$1.10, with whale activity and derivatives bets around $1.10 contributing to near-term volatility. | N15: 5 | O15: 5 | P15: 5 | Q15: 5

Sheet OpenAI Sumary
A1: OpenAI Output Validation Summary
A3: Criterion | B3: Average Score | C3: Maximum Score
A4: Relevance | B4: 5 | C4: 5
A5: Sentiment consistency | B5: 4.83 | C5: 5
A6: Factual grounding | B6: 4.58 | C6: 5
A7: Clarity | B7: 4.92 | C7: 5
A8: Conciseness | B8: 5 | C8: 5
A9: Market explanation quality | B9: 4.83 | C9: 5
A10: Safety | B10: 5 | C10: 5
A11: Overall Average | B11: 4.88 | C11: 5
A14: Compliance Measure | B14: Result
A15: Outputs containing 2–3 sentences | B15: 12 of 12 (100%)
A16: Outputs avoiding direct financial advice | B16: 12 of 12 (100%)
A17: Fallback/error messages returned | B17: 0 of 12 (0%)
A20: Key Observation | B20: Finding
A21: Strongest criteria | B21: Relevance, Conciseness, and Safety
A22: Lowest criterion | B22: Factual grounding
A23: Main weakness | B23: A small number of outputs introduced mild unsupported inferences or slightly misrepresented a supplied headline.
A24: Interpretation | B24: The outputs were generally relevant, clear, concise, safe, and consistent within the 12 tested scenarios.

Sheet Integration Tests
A1: AI Integration and Reliability Tests
A3: Test Condition | B3: Expected Result | C3: Actual Result | D3: Status
A4: Valid list of headlines submitted to FinBERT | B4: Sentiment labels, probabilities, risk score and risk level are returned
A5: Empty headline list submitted | B5: HTTP 400 response with "No texts provided"
A6: Valid positive headline | B6: Positive probability and predicted label are returned
A7: Valid negative headline | B7: Negative probability and predicted label are returned
A8: Valid neutral headline | B8: Neutral probability and predicted label are returned
A9: Calculated risk score below 35 | B9: Risk level is classified as Low
A10: Calculated risk score equal to 35 | B10: Risk level is classified as Medium
A11: Calculated risk score equal to 60 | B11: Risk level is classified as High
A12: OpenAI request succeeds | B12: Generated Market Abstract or Deep Dive explanation is returned
A13: OpenAI request fails | B13: Controlled fallback message is returned
A14: No asset-specific news is found | B14: Recent general cryptocurrency news is used as a fallback
A15: Unsupported Deep Dive symbol is submitted | B15: Request is rejected through validation
